[2024-01-16T06:52:00.958+0000] {taskinstance.py:1159} INFO - Dependencies all met for dep_context=non-requeueable deps ti=<TaskInstance: STT-files.STT manual__2024-01-16T06:50:10.427520+00:00 [queued]>
[2024-01-16T06:52:00.981+0000] {taskinstance.py:1159} INFO - Dependencies all met for dep_context=requeueable deps ti=<TaskInstance: STT-files.STT manual__2024-01-16T06:50:10.427520+00:00 [queued]>
[2024-01-16T06:52:00.983+0000] {taskinstance.py:1361} INFO - Starting attempt 2 of 2
[2024-01-16T06:52:01.007+0000] {taskinstance.py:1382} INFO - Executing <Task(PythonOperator): STT> on 2024-01-16 06:50:10.427520+00:00
[2024-01-16T06:52:01.054+0000] {standard_task_runner.py:57} INFO - Started process 301 to run task
[2024-01-16T06:52:01.060+0000] {standard_task_runner.py:84} INFO - Running: ['***', 'tasks', 'run', 'STT-files', 'STT', 'manual__2024-01-16T06:50:10.427520+00:00', '--job-id', '47', '--raw', '--subdir', 'DAGS_FOLDER/task.py', '--cfg-path', '/tmp/tmp_gcfrgqt']
[2024-01-16T06:52:01.070+0000] {standard_task_runner.py:85} INFO - Job 47: Subtask STT
[2024-01-16T06:52:01.179+0000] {task_command.py:416} INFO - Running <TaskInstance: STT-files.STT manual__2024-01-16T06:50:10.427520+00:00 [running]> on host 00276c0ab732
[2024-01-16T06:52:01.397+0000] {taskinstance.py:1662} INFO - Exporting env vars: AIRFLOW_CTX_DAG_OWNER='***' AIRFLOW_CTX_DAG_ID='STT-files' AIRFLOW_CTX_TASK_ID='STT' AIRFLOW_CTX_EXECUTION_DATE='2024-01-16T06:50:10.427520+00:00' AIRFLOW_CTX_TRY_NUMBER='2' AIRFLOW_CTX_DAG_RUN_ID='manual__2024-01-16T06:50:10.427520+00:00'
[2024-01-16T06:52:01.403+0000] {logging_mixin.py:154} INFO - b'{"language": "ko-KR", "completion": "sync", "callback": null, "userdata": null, "wordAlignment": true, "fullText": true, "forbiddens": null, "boostings": null, "diarization": null}'
[2024-01-16T06:52:11.970+0000] {taskinstance.py:1937} ERROR - Task failed with exception
Traceback (most recent call last):
  File "/home/airflow/.local/lib/python3.9/site-packages/pymysql/connections.py", line 644, in connect
    sock = socket.create_connection(
  File "/usr/local/lib/python3.9/socket.py", line 844, in create_connection
    raise err
  File "/usr/local/lib/python3.9/socket.py", line 832, in create_connection
    sock.connect(sa)
ConnectionRefusedError: [Errno 111] Connection refused

During handling of the above exception, another exception occurred:

Traceback (most recent call last):
  File "/home/airflow/.local/lib/python3.9/site-packages/airflow/operators/python.py", line 192, in execute
    return_value = self.execute_callable()
  File "/home/airflow/.local/lib/python3.9/site-packages/airflow/operators/python.py", line 209, in execute_callable
    return self.python_callable(*self.op_args, **self.op_kwargs)
  File "/opt/airflow/dags/function/clova_function.py", line 201, in STT
    user_id = get_user_id(user_name)
  File "/opt/airflow/dags/function/clova_function.py", line 142, in get_user_id
    connection = pymysql.connect(
  File "/home/airflow/.local/lib/python3.9/site-packages/pymysql/connections.py", line 358, in __init__
    self.connect()
  File "/home/airflow/.local/lib/python3.9/site-packages/pymysql/connections.py", line 711, in connect
    raise exc
pymysql.err.OperationalError: (2003, "Can't connect to MySQL server on '127.0.0.1' ([Errno 111] Connection refused)")
[2024-01-16T06:52:15.202+0000] {taskinstance.py:1400} INFO - Marking task as FAILED. dag_id=STT-files, task_id=STT, execution_date=20240116T065010, start_date=20240116T065200, end_date=20240116T065215
[2024-01-16T06:52:15.263+0000] {standard_task_runner.py:104} ERROR - Failed to execute job 47 for task STT ((2003, "Can't connect to MySQL server on '127.0.0.1' ([Errno 111] Connection refused)"); 301)
[2024-01-16T06:52:15.379+0000] {local_task_job_runner.py:228} INFO - Task exited with return code 1
[2024-01-16T06:52:15.428+0000] {taskinstance.py:2778} INFO - 0 downstream tasks scheduled from follow-on schedule check
