[2024-03-25T00:14:43.737+0000] {taskinstance.py:1159} INFO - Dependencies all met for dep_context=non-requeueable deps ti=<TaskInstance: stt_task.STT scheduled__2024-03-24T00:00:00+00:00 [queued]>
[2024-03-25T00:14:43.756+0000] {taskinstance.py:1159} INFO - Dependencies all met for dep_context=requeueable deps ti=<TaskInstance: stt_task.STT scheduled__2024-03-24T00:00:00+00:00 [queued]>
[2024-03-25T00:14:43.757+0000] {taskinstance.py:1361} INFO - Starting attempt 1 of 2
[2024-03-25T00:14:43.780+0000] {taskinstance.py:1382} INFO - Executing <Task(PythonOperator): STT> on 2024-03-24 00:00:00+00:00
[2024-03-25T00:14:43.789+0000] {standard_task_runner.py:57} INFO - Started process 1714 to run task
[2024-03-25T00:14:43.793+0000] {standard_task_runner.py:84} INFO - Running: ['***', 'tasks', 'run', 'stt_task', 'STT', 'scheduled__2024-03-24T00:00:00+00:00', '--job-id', '40', '--raw', '--subdir', 'DAGS_FOLDER/task.py', '--cfg-path', '/tmp/tmp9xjvab1b']
[2024-03-25T00:14:43.799+0000] {standard_task_runner.py:85} INFO - Job 40: Subtask STT
[2024-03-25T00:14:43.864+0000] {task_command.py:416} INFO - Running <TaskInstance: stt_task.STT scheduled__2024-03-24T00:00:00+00:00 [running]> on host 6fe5f6995c4e
[2024-03-25T00:14:43.979+0000] {taskinstance.py:1662} INFO - Exporting env vars: AIRFLOW_CTX_DAG_OWNER='***' AIRFLOW_CTX_DAG_ID='stt_task' AIRFLOW_CTX_TASK_ID='STT' AIRFLOW_CTX_EXECUTION_DATE='2024-03-24T00:00:00+00:00' AIRFLOW_CTX_TRY_NUMBER='1' AIRFLOW_CTX_DAG_RUN_ID='scheduled__2024-03-24T00:00:00+00:00'
[2024-03-25T00:14:43.989+0000] {taskinstance.py:1937} ERROR - Task failed with exception
Traceback (most recent call last):
  File "/home/airflow/.local/lib/python3.9/site-packages/airflow/operators/python.py", line 192, in execute
    return_value = self.execute_callable()
  File "/home/airflow/.local/lib/python3.9/site-packages/airflow/operators/python.py", line 209, in execute_callable
    return self.python_callable(*self.op_args, **self.op_kwargs)
  File "/opt/airflow/dags/task.py", line 52, in STT
    to_db(df)
UnboundLocalError: local variable 'df' referenced before assignment
[2024-03-25T00:14:44.011+0000] {taskinstance.py:1400} INFO - Marking task as UP_FOR_RETRY. dag_id=stt_task, task_id=STT, execution_date=20240324T000000, start_date=20240325T001443, end_date=20240325T001444
[2024-03-25T00:14:44.035+0000] {standard_task_runner.py:104} ERROR - Failed to execute job 40 for task STT (local variable 'df' referenced before assignment; 1714)
[2024-03-25T00:14:44.056+0000] {local_task_job_runner.py:228} INFO - Task exited with return code 1
[2024-03-25T00:14:44.078+0000] {taskinstance.py:2778} INFO - 0 downstream tasks scheduled from follow-on schedule check
