[2024-04-02T14:06:13.646+0000] {taskinstance.py:1159} INFO - Dependencies all met for dep_context=non-requeueable deps ti=<TaskInstance: stt_task.STT manual__2024-04-02T14:06:11.531448+00:00 [queued]>
[2024-04-02T14:06:13.666+0000] {taskinstance.py:1159} INFO - Dependencies all met for dep_context=requeueable deps ti=<TaskInstance: stt_task.STT manual__2024-04-02T14:06:11.531448+00:00 [queued]>
[2024-04-02T14:06:13.667+0000] {taskinstance.py:1361} INFO - Starting attempt 1 of 2
[2024-04-02T14:06:13.698+0000] {taskinstance.py:1382} INFO - Executing <Task(PythonOperator): STT> on 2024-04-02 14:06:11.531448+00:00
[2024-04-02T14:06:13.704+0000] {standard_task_runner.py:57} INFO - Started process 2262 to run task
[2024-04-02T14:06:13.708+0000] {standard_task_runner.py:84} INFO - Running: ['***', 'tasks', 'run', 'stt_task', 'STT', 'manual__2024-04-02T14:06:11.531448+00:00', '--job-id', '79', '--raw', '--subdir', 'DAGS_FOLDER/task.py', '--cfg-path', '/tmp/tmpx0m3468m']
[2024-04-02T14:06:13.717+0000] {standard_task_runner.py:85} INFO - Job 79: Subtask STT
[2024-04-02T14:06:13.794+0000] {task_command.py:416} INFO - Running <TaskInstance: stt_task.STT manual__2024-04-02T14:06:11.531448+00:00 [running]> on host bd3757cb365e
[2024-04-02T14:06:13.914+0000] {taskinstance.py:1662} INFO - Exporting env vars: AIRFLOW_CTX_DAG_OWNER='***' AIRFLOW_CTX_DAG_ID='stt_task' AIRFLOW_CTX_TASK_ID='STT' AIRFLOW_CTX_EXECUTION_DATE='2024-04-02T14:06:11.531448+00:00' AIRFLOW_CTX_TRY_NUMBER='1' AIRFLOW_CTX_DAG_RUN_ID='manual__2024-04-02T14:06:11.531448+00:00'
[2024-04-02T14:06:13.918+0000] {logging_mixin.py:154} INFO - b'{"language": "ko-KR", "completion": "sync", "callback": null, "userdata": null, "wordAlignment": true, "fullText": true, "forbiddens": null, "boostings": null, "diarization": true}'
[2024-04-02T14:06:16.413+0000] {taskinstance.py:1937} ERROR - Task failed with exception
Traceback (most recent call last):
  File "/home/airflow/.local/lib/python3.9/site-packages/airflow/operators/python.py", line 192, in execute
    return_value = self.execute_callable()
  File "/home/airflow/.local/lib/python3.9/site-packages/airflow/operators/python.py", line 209, in execute_callable
    return self.python_callable(*self.op_args, **self.op_kwargs)
  File "/opt/airflow/dags/task.py", line 24, in STT
    segments = data['segments']
KeyError: 'segments'
[2024-04-02T14:06:16.435+0000] {taskinstance.py:1400} INFO - Marking task as UP_FOR_RETRY. dag_id=stt_task, task_id=STT, execution_date=20240402T140611, start_date=20240402T140613, end_date=20240402T140616
[2024-04-02T14:06:16.457+0000] {standard_task_runner.py:104} ERROR - Failed to execute job 79 for task STT ('segments'; 2262)
[2024-04-02T14:06:16.509+0000] {local_task_job_runner.py:228} INFO - Task exited with return code 1
[2024-04-02T14:06:16.536+0000] {taskinstance.py:2778} INFO - 0 downstream tasks scheduled from follow-on schedule check
