[2024-01-19T08:38:03.848+0000] {taskinstance.py:1159} INFO - Dependencies all met for dep_context=non-requeueable deps ti=<TaskInstance: stt_task.STT scheduled__2024-01-18T00:00:00+00:00 [queued]>
[2024-01-19T08:38:03.861+0000] {taskinstance.py:1159} INFO - Dependencies all met for dep_context=requeueable deps ti=<TaskInstance: stt_task.STT scheduled__2024-01-18T00:00:00+00:00 [queued]>
[2024-01-19T08:38:03.862+0000] {taskinstance.py:1361} INFO - Starting attempt 2 of 2
[2024-01-19T08:38:03.881+0000] {taskinstance.py:1382} INFO - Executing <Task(PythonOperator): STT> on 2024-01-18 00:00:00+00:00
[2024-01-19T08:38:03.892+0000] {standard_task_runner.py:57} INFO - Started process 75 to run task
[2024-01-19T08:38:03.896+0000] {standard_task_runner.py:84} INFO - Running: ['***', 'tasks', 'run', 'stt_task', 'STT', 'scheduled__2024-01-18T00:00:00+00:00', '--job-id', '74', '--raw', '--subdir', 'DAGS_FOLDER/task.py', '--cfg-path', '/tmp/tmpia7zqr7b']
[2024-01-19T08:38:03.901+0000] {standard_task_runner.py:85} INFO - Job 74: Subtask STT
[2024-01-19T08:38:03.960+0000] {task_command.py:416} INFO - Running <TaskInstance: stt_task.STT scheduled__2024-01-18T00:00:00+00:00 [running]> on host a8fcb1faa919
[2024-01-19T08:38:04.056+0000] {taskinstance.py:1662} INFO - Exporting env vars: AIRFLOW_CTX_DAG_OWNER='***' AIRFLOW_CTX_DAG_ID='stt_task' AIRFLOW_CTX_TASK_ID='STT' AIRFLOW_CTX_EXECUTION_DATE='2024-01-18T00:00:00+00:00' AIRFLOW_CTX_TRY_NUMBER='2' AIRFLOW_CTX_DAG_RUN_ID='scheduled__2024-01-18T00:00:00+00:00'
[2024-01-19T08:38:04.062+0000] {taskinstance.py:1937} ERROR - Task failed with exception
Traceback (most recent call last):
  File "/home/airflow/.local/lib/python3.9/site-packages/airflow/operators/python.py", line 192, in execute
    return_value = self.execute_callable()
  File "/home/airflow/.local/lib/python3.9/site-packages/airflow/operators/python.py", line 209, in execute_callable
    return self.python_callable(*self.op_args, **self.op_kwargs)
  File "/opt/airflow/dags/task.py", line 52, in STT
    to_db(table = 'STT', df = df)
UnboundLocalError: local variable 'df' referenced before assignment
[2024-01-19T08:38:04.074+0000] {taskinstance.py:1400} INFO - Marking task as FAILED. dag_id=stt_task, task_id=STT, execution_date=20240118T000000, start_date=20240119T083803, end_date=20240119T083804
[2024-01-19T08:38:04.089+0000] {standard_task_runner.py:104} ERROR - Failed to execute job 74 for task STT (local variable 'df' referenced before assignment; 75)
[2024-01-19T08:38:04.111+0000] {local_task_job_runner.py:228} INFO - Task exited with return code 1
[2024-01-19T08:38:04.132+0000] {taskinstance.py:2778} INFO - 0 downstream tasks scheduled from follow-on schedule check
