[2024-04-02T11:14:16.826+0000] {taskinstance.py:1159} INFO - Dependencies all met for dep_context=non-requeueable deps ti=<TaskInstance: stt_task.STT manual__2024-04-02T11:13:12.891830+00:00 [queued]>
[2024-04-02T11:14:16.842+0000] {taskinstance.py:1159} INFO - Dependencies all met for dep_context=requeueable deps ti=<TaskInstance: stt_task.STT manual__2024-04-02T11:13:12.891830+00:00 [queued]>
[2024-04-02T11:14:16.843+0000] {taskinstance.py:1361} INFO - Starting attempt 2 of 2
[2024-04-02T11:14:16.858+0000] {taskinstance.py:1382} INFO - Executing <Task(PythonOperator): STT> on 2024-04-02 11:13:12.891830+00:00
[2024-04-02T11:14:16.865+0000] {standard_task_runner.py:57} INFO - Started process 79 to run task
[2024-04-02T11:14:16.869+0000] {standard_task_runner.py:84} INFO - Running: ['***', 'tasks', 'run', 'stt_task', 'STT', 'manual__2024-04-02T11:13:12.891830+00:00', '--job-id', '61', '--raw', '--subdir', 'DAGS_FOLDER/task.py', '--cfg-path', '/tmp/tmpdcqoim7r']
[2024-04-02T11:14:16.873+0000] {standard_task_runner.py:85} INFO - Job 61: Subtask STT
[2024-04-02T11:14:16.933+0000] {task_command.py:416} INFO - Running <TaskInstance: stt_task.STT manual__2024-04-02T11:13:12.891830+00:00 [running]> on host bd3757cb365e
[2024-04-02T11:14:17.025+0000] {taskinstance.py:1662} INFO - Exporting env vars: AIRFLOW_CTX_DAG_OWNER='***' AIRFLOW_CTX_DAG_ID='stt_task' AIRFLOW_CTX_TASK_ID='STT' AIRFLOW_CTX_EXECUTION_DATE='2024-04-02T11:13:12.891830+00:00' AIRFLOW_CTX_TRY_NUMBER='2' AIRFLOW_CTX_DAG_RUN_ID='manual__2024-04-02T11:13:12.891830+00:00'
[2024-04-02T11:14:17.029+0000] {taskinstance.py:1937} ERROR - Task failed with exception
Traceback (most recent call last):
  File "/home/airflow/.local/lib/python3.9/site-packages/airflow/operators/python.py", line 192, in execute
    return_value = self.execute_callable()
  File "/home/airflow/.local/lib/python3.9/site-packages/airflow/operators/python.py", line 209, in execute_callable
    return self.python_callable(*self.op_args, **self.op_kwargs)
  File "/opt/airflow/dags/task.py", line 58, in STT
    to_db(df)
UnboundLocalError: local variable 'df' referenced before assignment
[2024-04-02T11:14:17.042+0000] {taskinstance.py:1400} INFO - Marking task as FAILED. dag_id=stt_task, task_id=STT, execution_date=20240402T111312, start_date=20240402T111416, end_date=20240402T111417
[2024-04-02T11:14:17.058+0000] {standard_task_runner.py:104} ERROR - Failed to execute job 61 for task STT (local variable 'df' referenced before assignment; 79)
[2024-04-02T11:14:17.083+0000] {local_task_job_runner.py:228} INFO - Task exited with return code 1
[2024-04-02T11:14:17.102+0000] {taskinstance.py:2778} INFO - 0 downstream tasks scheduled from follow-on schedule check
