[2024-01-16T07:01:02.564+0000] {taskinstance.py:1159} INFO - Dependencies all met for dep_context=non-requeueable deps ti=<TaskInstance: stt_task.STT scheduled__2024-01-15T00:00:00+00:00 [queued]>
[2024-01-16T07:01:02.578+0000] {taskinstance.py:1159} INFO - Dependencies all met for dep_context=requeueable deps ti=<TaskInstance: stt_task.STT scheduled__2024-01-15T00:00:00+00:00 [queued]>
[2024-01-16T07:01:02.579+0000] {taskinstance.py:1361} INFO - Starting attempt 1 of 2
[2024-01-16T07:01:02.597+0000] {taskinstance.py:1382} INFO - Executing <Task(PythonOperator): STT> on 2024-01-15 00:00:00+00:00
[2024-01-16T07:01:02.604+0000] {standard_task_runner.py:57} INFO - Started process 422 to run task
[2024-01-16T07:01:02.608+0000] {standard_task_runner.py:84} INFO - Running: ['***', 'tasks', 'run', 'stt_task', 'STT', 'scheduled__2024-01-15T00:00:00+00:00', '--job-id', '51', '--raw', '--subdir', 'DAGS_FOLDER/task.py', '--cfg-path', '/tmp/tmpo2psvg6i']
[2024-01-16T07:01:02.612+0000] {standard_task_runner.py:85} INFO - Job 51: Subtask STT
[2024-01-16T07:01:02.677+0000] {task_command.py:416} INFO - Running <TaskInstance: stt_task.STT scheduled__2024-01-15T00:00:00+00:00 [running]> on host 00276c0ab732
[2024-01-16T07:01:02.773+0000] {taskinstance.py:1662} INFO - Exporting env vars: AIRFLOW_CTX_DAG_OWNER='***' AIRFLOW_CTX_DAG_ID='stt_task' AIRFLOW_CTX_TASK_ID='STT' AIRFLOW_CTX_EXECUTION_DATE='2024-01-15T00:00:00+00:00' AIRFLOW_CTX_TRY_NUMBER='1' AIRFLOW_CTX_DAG_RUN_ID='scheduled__2024-01-15T00:00:00+00:00'
[2024-01-16T07:01:02.778+0000] {logging_mixin.py:154} INFO - b'{"language": "ko-KR", "completion": "sync", "callback": null, "userdata": null, "wordAlignment": true, "fullText": true, "forbiddens": null, "boostings": null, "diarization": null}'
[2024-01-16T07:01:11.119+0000] {taskinstance.py:1937} ERROR - Task failed with exception
Traceback (most recent call last):
  File "/home/airflow/.local/lib/python3.9/site-packages/airflow/operators/python.py", line 192, in execute
    return_value = self.execute_callable()
  File "/home/airflow/.local/lib/python3.9/site-packages/airflow/operators/python.py", line 209, in execute_callable
    return self.python_callable(*self.op_args, **self.op_kwargs)
  File "/opt/airflow/dags/task.py", line 24, in STT
    data = json.loads(clova_output)
NameError: name 'json' is not defined
[2024-01-16T07:01:11.131+0000] {taskinstance.py:1400} INFO - Marking task as UP_FOR_RETRY. dag_id=stt_task, task_id=STT, execution_date=20240115T000000, start_date=20240116T070102, end_date=20240116T070111
[2024-01-16T07:01:11.151+0000] {standard_task_runner.py:104} ERROR - Failed to execute job 51 for task STT (name 'json' is not defined; 422)
[2024-01-16T07:01:11.171+0000] {local_task_job_runner.py:228} INFO - Task exited with return code 1
[2024-01-16T07:01:11.191+0000] {taskinstance.py:2778} INFO - 0 downstream tasks scheduled from follow-on schedule check
