[2024-03-24T05:05:09.974+0000] {taskinstance.py:1159} INFO - Dependencies all met for dep_context=non-requeueable deps ti=<TaskInstance: stt_task.STT manual__2024-03-24T05:03:54.795200+00:00 [queued]>
[2024-03-24T05:05:09.990+0000] {taskinstance.py:1159} INFO - Dependencies all met for dep_context=requeueable deps ti=<TaskInstance: stt_task.STT manual__2024-03-24T05:03:54.795200+00:00 [queued]>
[2024-03-24T05:05:09.991+0000] {taskinstance.py:1361} INFO - Starting attempt 2 of 2
[2024-03-24T05:05:10.015+0000] {taskinstance.py:1382} INFO - Executing <Task(PythonOperator): STT> on 2024-03-24 05:03:54.795200+00:00
[2024-03-24T05:05:10.022+0000] {standard_task_runner.py:57} INFO - Started process 254 to run task
[2024-03-24T05:05:10.026+0000] {standard_task_runner.py:84} INFO - Running: ['***', 'tasks', 'run', 'stt_task', 'STT', 'manual__2024-03-24T05:03:54.795200+00:00', '--job-id', '29', '--raw', '--subdir', 'DAGS_FOLDER/task.py', '--cfg-path', '/tmp/tmp7gojh4x1']
[2024-03-24T05:05:10.032+0000] {standard_task_runner.py:85} INFO - Job 29: Subtask STT
[2024-03-24T05:05:10.104+0000] {task_command.py:416} INFO - Running <TaskInstance: stt_task.STT manual__2024-03-24T05:03:54.795200+00:00 [running]> on host 1b48040cfa26
[2024-03-24T05:05:10.254+0000] {taskinstance.py:1662} INFO - Exporting env vars: AIRFLOW_CTX_DAG_OWNER='***' AIRFLOW_CTX_DAG_ID='stt_task' AIRFLOW_CTX_TASK_ID='STT' AIRFLOW_CTX_EXECUTION_DATE='2024-03-24T05:03:54.795200+00:00' AIRFLOW_CTX_TRY_NUMBER='2' AIRFLOW_CTX_DAG_RUN_ID='manual__2024-03-24T05:03:54.795200+00:00'
[2024-03-24T05:05:10.258+0000] {logging_mixin.py:154} INFO - b'{"language": "ko-KR", "completion": "sync", "callback": null, "userdata": null, "wordAlignment": true, "fullText": true, "forbiddens": null, "boostings": null, "diarization": null}'
[2024-03-24T05:05:18.168+0000] {taskinstance.py:1937} ERROR - Task failed with exception
Traceback (most recent call last):
  File "/home/airflow/.local/lib/python3.9/site-packages/pymysql/connections.py", line 644, in connect
    sock = socket.create_connection(
  File "/usr/local/lib/python3.9/socket.py", line 823, in create_connection
    for res in getaddrinfo(host, port, 0, SOCK_STREAM):
  File "/usr/local/lib/python3.9/socket.py", line 954, in getaddrinfo
    for res in _socket.getaddrinfo(host, port, family, type, proto, flags):
socket.gaierror: [Errno -2] Name or service not known

During handling of the above exception, another exception occurred:

Traceback (most recent call last):
  File "/home/airflow/.local/lib/python3.9/site-packages/airflow/operators/python.py", line 192, in execute
    return_value = self.execute_callable()
  File "/home/airflow/.local/lib/python3.9/site-packages/airflow/operators/python.py", line 209, in execute_callable
    return self.python_callable(*self.op_args, **self.op_kwargs)
  File "/opt/airflow/dags/task.py", line 45, in STT
    user_id = get_user_id(user_name)
  File "/opt/airflow/dags/function/clova_function.py", line 142, in get_user_id
    connection = pymysql.connect(
  File "/home/airflow/.local/lib/python3.9/site-packages/pymysql/connections.py", line 358, in __init__
    self.connect()
  File "/home/airflow/.local/lib/python3.9/site-packages/pymysql/connections.py", line 711, in connect
    raise exc
pymysql.err.OperationalError: (2003, "Can't connect to MySQL server on 'mysql' ([Errno -2] Name or service not known)")
[2024-03-24T05:05:18.185+0000] {taskinstance.py:1400} INFO - Marking task as FAILED. dag_id=stt_task, task_id=STT, execution_date=20240324T050354, start_date=20240324T050509, end_date=20240324T050518
[2024-03-24T05:05:18.451+0000] {standard_task_runner.py:104} ERROR - Failed to execute job 29 for task STT ((2003, "Can't connect to MySQL server on 'mysql' ([Errno -2] Name or service not known)"); 254)
[2024-03-24T05:05:18.492+0000] {local_task_job_runner.py:228} INFO - Task exited with return code 1
[2024-03-24T05:05:18.528+0000] {taskinstance.py:2778} INFO - 0 downstream tasks scheduled from follow-on schedule check
