[2024-01-16T07:02:15.414+0000] {taskinstance.py:1159} INFO - Dependencies all met for dep_context=non-requeueable deps ti=<TaskInstance: stt_task.STT manual__2024-01-16T07:01:00.889485+00:00 [queued]>
[2024-01-16T07:02:15.433+0000] {taskinstance.py:1159} INFO - Dependencies all met for dep_context=requeueable deps ti=<TaskInstance: stt_task.STT manual__2024-01-16T07:01:00.889485+00:00 [queued]>
[2024-01-16T07:02:15.434+0000] {taskinstance.py:1361} INFO - Starting attempt 2 of 2
[2024-01-16T07:02:15.452+0000] {taskinstance.py:1382} INFO - Executing <Task(PythonOperator): STT> on 2024-01-16 07:01:00.889485+00:00
[2024-01-16T07:02:15.460+0000] {standard_task_runner.py:57} INFO - Started process 443 to run task
[2024-01-16T07:02:15.464+0000] {standard_task_runner.py:84} INFO - Running: ['***', 'tasks', 'run', 'stt_task', 'STT', 'manual__2024-01-16T07:01:00.889485+00:00', '--job-id', '54', '--raw', '--subdir', 'DAGS_FOLDER/task.py', '--cfg-path', '/tmp/tmpc1kjis19']
[2024-01-16T07:02:15.469+0000] {standard_task_runner.py:85} INFO - Job 54: Subtask STT
[2024-01-16T07:02:15.530+0000] {task_command.py:416} INFO - Running <TaskInstance: stt_task.STT manual__2024-01-16T07:01:00.889485+00:00 [running]> on host 00276c0ab732
[2024-01-16T07:02:15.626+0000] {taskinstance.py:1662} INFO - Exporting env vars: AIRFLOW_CTX_DAG_OWNER='***' AIRFLOW_CTX_DAG_ID='stt_task' AIRFLOW_CTX_TASK_ID='STT' AIRFLOW_CTX_EXECUTION_DATE='2024-01-16T07:01:00.889485+00:00' AIRFLOW_CTX_TRY_NUMBER='2' AIRFLOW_CTX_DAG_RUN_ID='manual__2024-01-16T07:01:00.889485+00:00'
[2024-01-16T07:02:15.629+0000] {logging_mixin.py:154} INFO - b'{"language": "ko-KR", "completion": "sync", "callback": null, "userdata": null, "wordAlignment": true, "fullText": true, "forbiddens": null, "boostings": null, "diarization": null}'
[2024-01-16T07:02:26.493+0000] {taskinstance.py:1937} ERROR - Task failed with exception
Traceback (most recent call last):
  File "/home/airflow/.local/lib/python3.9/site-packages/airflow/operators/python.py", line 192, in execute
    return_value = self.execute_callable()
  File "/home/airflow/.local/lib/python3.9/site-packages/airflow/operators/python.py", line 209, in execute_callable
    return self.python_callable(*self.op_args, **self.op_kwargs)
  File "/opt/airflow/dags/task.py", line 24, in STT
    data = json.loads(clova_output)
NameError: name 'json' is not defined
[2024-01-16T07:02:26.508+0000] {taskinstance.py:1400} INFO - Marking task as FAILED. dag_id=stt_task, task_id=STT, execution_date=20240116T070100, start_date=20240116T070215, end_date=20240116T070226
[2024-01-16T07:02:26.527+0000] {standard_task_runner.py:104} ERROR - Failed to execute job 54 for task STT (name 'json' is not defined; 443)
[2024-01-16T07:02:26.565+0000] {local_task_job_runner.py:228} INFO - Task exited with return code 1
[2024-01-16T07:02:26.584+0000] {taskinstance.py:2778} INFO - 0 downstream tasks scheduled from follow-on schedule check
