[2024-01-16T07:01:03.080+0000] {taskinstance.py:1159} INFO - Dependencies all met for dep_context=non-requeueable deps ti=<TaskInstance: stt_task.STT manual__2024-01-16T07:01:00.889485+00:00 [queued]>
[2024-01-16T07:01:03.096+0000] {taskinstance.py:1159} INFO - Dependencies all met for dep_context=requeueable deps ti=<TaskInstance: stt_task.STT manual__2024-01-16T07:01:00.889485+00:00 [queued]>
[2024-01-16T07:01:03.097+0000] {taskinstance.py:1361} INFO - Starting attempt 1 of 2
[2024-01-16T07:01:03.119+0000] {taskinstance.py:1382} INFO - Executing <Task(PythonOperator): STT> on 2024-01-16 07:01:00.889485+00:00
[2024-01-16T07:01:03.127+0000] {standard_task_runner.py:57} INFO - Started process 423 to run task
[2024-01-16T07:01:03.132+0000] {standard_task_runner.py:84} INFO - Running: ['***', 'tasks', 'run', 'stt_task', 'STT', 'manual__2024-01-16T07:01:00.889485+00:00', '--job-id', '52', '--raw', '--subdir', 'DAGS_FOLDER/task.py', '--cfg-path', '/tmp/tmp8ac5ia9c']
[2024-01-16T07:01:03.136+0000] {standard_task_runner.py:85} INFO - Job 52: Subtask STT
[2024-01-16T07:01:03.240+0000] {task_command.py:416} INFO - Running <TaskInstance: stt_task.STT manual__2024-01-16T07:01:00.889485+00:00 [running]> on host 00276c0ab732
[2024-01-16T07:01:03.340+0000] {taskinstance.py:1662} INFO - Exporting env vars: AIRFLOW_CTX_DAG_OWNER='***' AIRFLOW_CTX_DAG_ID='stt_task' AIRFLOW_CTX_TASK_ID='STT' AIRFLOW_CTX_EXECUTION_DATE='2024-01-16T07:01:00.889485+00:00' AIRFLOW_CTX_TRY_NUMBER='1' AIRFLOW_CTX_DAG_RUN_ID='manual__2024-01-16T07:01:00.889485+00:00'
[2024-01-16T07:01:03.344+0000] {logging_mixin.py:154} INFO - b'{"language": "ko-KR", "completion": "sync", "callback": null, "userdata": null, "wordAlignment": true, "fullText": true, "forbiddens": null, "boostings": null, "diarization": null}'
[2024-01-16T07:01:14.633+0000] {taskinstance.py:1937} ERROR - Task failed with exception
Traceback (most recent call last):
  File "/home/airflow/.local/lib/python3.9/site-packages/airflow/operators/python.py", line 192, in execute
    return_value = self.execute_callable()
  File "/home/airflow/.local/lib/python3.9/site-packages/airflow/operators/python.py", line 209, in execute_callable
    return self.python_callable(*self.op_args, **self.op_kwargs)
  File "/opt/airflow/dags/task.py", line 24, in STT
    data = json.loads(clova_output)
NameError: name 'json' is not defined
[2024-01-16T07:01:14.652+0000] {taskinstance.py:1400} INFO - Marking task as UP_FOR_RETRY. dag_id=stt_task, task_id=STT, execution_date=20240116T070100, start_date=20240116T070103, end_date=20240116T070114
[2024-01-16T07:01:14.671+0000] {standard_task_runner.py:104} ERROR - Failed to execute job 52 for task STT (name 'json' is not defined; 423)
[2024-01-16T07:01:14.690+0000] {local_task_job_runner.py:228} INFO - Task exited with return code 1
[2024-01-16T07:01:14.730+0000] {taskinstance.py:2778} INFO - 0 downstream tasks scheduled from follow-on schedule check
