[2024-01-17T07:07:13.975+0000] {taskinstance.py:1159} INFO - Dependencies all met for dep_context=non-requeueable deps ti=<TaskInstance: stt_task.STT scheduled__2024-01-16T00:00:00+00:00 [queued]>
[2024-01-17T07:07:13.995+0000] {taskinstance.py:1159} INFO - Dependencies all met for dep_context=requeueable deps ti=<TaskInstance: stt_task.STT scheduled__2024-01-16T00:00:00+00:00 [queued]>
[2024-01-17T07:07:13.997+0000] {taskinstance.py:1361} INFO - Starting attempt 2 of 2
[2024-01-17T07:07:14.018+0000] {taskinstance.py:1382} INFO - Executing <Task(PythonOperator): STT> on 2024-01-16 00:00:00+00:00
[2024-01-17T07:07:14.030+0000] {standard_task_runner.py:57} INFO - Started process 75 to run task
[2024-01-17T07:07:14.035+0000] {standard_task_runner.py:84} INFO - Running: ['***', 'tasks', 'run', 'stt_task', 'STT', 'scheduled__2024-01-16T00:00:00+00:00', '--job-id', '61', '--raw', '--subdir', 'DAGS_FOLDER/task.py', '--cfg-path', '/tmp/tmpxx43w330']
[2024-01-17T07:07:14.039+0000] {standard_task_runner.py:85} INFO - Job 61: Subtask STT
[2024-01-17T07:07:14.132+0000] {task_command.py:416} INFO - Running <TaskInstance: stt_task.STT scheduled__2024-01-16T00:00:00+00:00 [running]> on host 33ce4c84e7d8
[2024-01-17T07:07:14.264+0000] {taskinstance.py:1662} INFO - Exporting env vars: AIRFLOW_CTX_DAG_OWNER='***' AIRFLOW_CTX_DAG_ID='stt_task' AIRFLOW_CTX_TASK_ID='STT' AIRFLOW_CTX_EXECUTION_DATE='2024-01-16T00:00:00+00:00' AIRFLOW_CTX_TRY_NUMBER='2' AIRFLOW_CTX_DAG_RUN_ID='scheduled__2024-01-16T00:00:00+00:00'
[2024-01-17T07:07:14.269+0000] {taskinstance.py:1937} ERROR - Task failed with exception
Traceback (most recent call last):
  File "/home/airflow/.local/lib/python3.9/site-packages/airflow/operators/python.py", line 192, in execute
    return_value = self.execute_callable()
  File "/home/airflow/.local/lib/python3.9/site-packages/airflow/operators/python.py", line 209, in execute_callable
    return self.python_callable(*self.op_args, **self.op_kwargs)
  File "/opt/airflow/dags/task.py", line 52, in STT
    to_db(table = 'STT', df = df)
UnboundLocalError: local variable 'df' referenced before assignment
[2024-01-17T07:07:14.286+0000] {taskinstance.py:1400} INFO - Marking task as FAILED. dag_id=stt_task, task_id=STT, execution_date=20240116T000000, start_date=20240117T070713, end_date=20240117T070714
[2024-01-17T07:07:14.310+0000] {standard_task_runner.py:104} ERROR - Failed to execute job 61 for task STT (local variable 'df' referenced before assignment; 75)
[2024-01-17T07:07:14.333+0000] {local_task_job_runner.py:228} INFO - Task exited with return code 1
[2024-01-17T07:07:14.370+0000] {taskinstance.py:2778} INFO - 0 downstream tasks scheduled from follow-on schedule check
[2024-01-17T07:12:49.618+0000] {taskinstance.py:1159} INFO - Dependencies all met for dep_context=non-requeueable deps ti=<TaskInstance: stt_task.STT scheduled__2024-01-16T00:00:00+00:00 [queued]>
[2024-01-17T07:12:49.663+0000] {taskinstance.py:1159} INFO - Dependencies all met for dep_context=requeueable deps ti=<TaskInstance: stt_task.STT scheduled__2024-01-16T00:00:00+00:00 [queued]>
[2024-01-17T07:12:49.664+0000] {taskinstance.py:1361} INFO - Starting attempt 2 of 2
[2024-01-17T07:12:49.714+0000] {taskinstance.py:1382} INFO - Executing <Task(PythonOperator): STT> on 2024-01-16 00:00:00+00:00
[2024-01-17T07:12:49.730+0000] {standard_task_runner.py:57} INFO - Started process 161 to run task
[2024-01-17T07:12:49.735+0000] {standard_task_runner.py:84} INFO - Running: ['***', 'tasks', 'run', 'stt_task', 'STT', 'scheduled__2024-01-16T00:00:00+00:00', '--job-id', '65', '--raw', '--subdir', 'DAGS_FOLDER/task.py', '--cfg-path', '/tmp/tmpgjel1uul']
[2024-01-17T07:12:49.751+0000] {standard_task_runner.py:85} INFO - Job 65: Subtask STT
[2024-01-17T07:12:49.857+0000] {task_command.py:416} INFO - Running <TaskInstance: stt_task.STT scheduled__2024-01-16T00:00:00+00:00 [running]> on host 33ce4c84e7d8
[2024-01-17T07:12:50.070+0000] {taskinstance.py:1662} INFO - Exporting env vars: AIRFLOW_CTX_DAG_OWNER='***' AIRFLOW_CTX_DAG_ID='stt_task' AIRFLOW_CTX_TASK_ID='STT' AIRFLOW_CTX_EXECUTION_DATE='2024-01-16T00:00:00+00:00' AIRFLOW_CTX_TRY_NUMBER='2' AIRFLOW_CTX_DAG_RUN_ID='scheduled__2024-01-16T00:00:00+00:00'
[2024-01-17T07:12:50.080+0000] {taskinstance.py:1937} ERROR - Task failed with exception
Traceback (most recent call last):
  File "/home/airflow/.local/lib/python3.9/site-packages/airflow/operators/python.py", line 192, in execute
    return_value = self.execute_callable()
  File "/home/airflow/.local/lib/python3.9/site-packages/airflow/operators/python.py", line 209, in execute_callable
    return self.python_callable(*self.op_args, **self.op_kwargs)
  File "/opt/airflow/dags/task.py", line 52, in STT
    to_db(table = 'STT', df = df)
UnboundLocalError: local variable 'df' referenced before assignment
[2024-01-17T07:12:50.157+0000] {taskinstance.py:1400} INFO - Marking task as FAILED. dag_id=stt_task, task_id=STT, execution_date=20240116T000000, start_date=20240117T071249, end_date=20240117T071250
[2024-01-17T07:12:50.193+0000] {standard_task_runner.py:104} ERROR - Failed to execute job 65 for task STT (local variable 'df' referenced before assignment; 161)
[2024-01-17T07:12:50.226+0000] {local_task_job_runner.py:228} INFO - Task exited with return code 1
[2024-01-17T07:12:50.258+0000] {taskinstance.py:2778} INFO - 0 downstream tasks scheduled from follow-on schedule check
