[2024-01-17T07:06:08.881+0000] {taskinstance.py:1159} INFO - Dependencies all met for dep_context=non-requeueable deps ti=<TaskInstance: stt_task.STT scheduled__2024-01-16T00:00:00+00:00 [queued]>
[2024-01-17T07:06:08.903+0000] {taskinstance.py:1159} INFO - Dependencies all met for dep_context=requeueable deps ti=<TaskInstance: stt_task.STT scheduled__2024-01-16T00:00:00+00:00 [queued]>
[2024-01-17T07:06:08.904+0000] {taskinstance.py:1361} INFO - Starting attempt 1 of 2
[2024-01-17T07:06:08.929+0000] {taskinstance.py:1382} INFO - Executing <Task(PythonOperator): STT> on 2024-01-16 00:00:00+00:00
[2024-01-17T07:06:08.945+0000] {standard_task_runner.py:57} INFO - Started process 58 to run task
[2024-01-17T07:06:08.967+0000] {standard_task_runner.py:84} INFO - Running: ['***', 'tasks', 'run', 'stt_task', 'STT', 'scheduled__2024-01-16T00:00:00+00:00', '--job-id', '60', '--raw', '--subdir', 'DAGS_FOLDER/task.py', '--cfg-path', '/tmp/tmp1lw_cbd2']
[2024-01-17T07:06:09.013+0000] {standard_task_runner.py:85} INFO - Job 60: Subtask STT
[2024-01-17T07:06:09.541+0000] {task_command.py:416} INFO - Running <TaskInstance: stt_task.STT scheduled__2024-01-16T00:00:00+00:00 [running]> on host 33ce4c84e7d8
[2024-01-17T07:06:12.378+0000] {taskinstance.py:1662} INFO - Exporting env vars: AIRFLOW_CTX_DAG_OWNER='***' AIRFLOW_CTX_DAG_ID='stt_task' AIRFLOW_CTX_TASK_ID='STT' AIRFLOW_CTX_EXECUTION_DATE='2024-01-16T00:00:00+00:00' AIRFLOW_CTX_TRY_NUMBER='1' AIRFLOW_CTX_DAG_RUN_ID='scheduled__2024-01-16T00:00:00+00:00'
[2024-01-17T07:06:12.390+0000] {taskinstance.py:1937} ERROR - Task failed with exception
Traceback (most recent call last):
  File "/home/airflow/.local/lib/python3.9/site-packages/airflow/operators/python.py", line 192, in execute
    return_value = self.execute_callable()
  File "/home/airflow/.local/lib/python3.9/site-packages/airflow/operators/python.py", line 209, in execute_callable
    return self.python_callable(*self.op_args, **self.op_kwargs)
  File "/opt/airflow/dags/task.py", line 52, in STT
    to_db(table = 'STT', df = df)
UnboundLocalError: local variable 'df' referenced before assignment
[2024-01-17T07:06:12.413+0000] {taskinstance.py:1400} INFO - Marking task as UP_FOR_RETRY. dag_id=stt_task, task_id=STT, execution_date=20240116T000000, start_date=20240117T070608, end_date=20240117T070612
[2024-01-17T07:06:12.453+0000] {standard_task_runner.py:104} ERROR - Failed to execute job 60 for task STT (local variable 'df' referenced before assignment; 58)
[2024-01-17T07:06:12.510+0000] {local_task_job_runner.py:228} INFO - Task exited with return code 1
[2024-01-17T07:06:12.550+0000] {taskinstance.py:2778} INFO - 0 downstream tasks scheduled from follow-on schedule check
[2024-01-17T07:11:47.320+0000] {taskinstance.py:1159} INFO - Dependencies all met for dep_context=non-requeueable deps ti=<TaskInstance: stt_task.STT scheduled__2024-01-16T00:00:00+00:00 [queued]>
[2024-01-17T07:11:47.337+0000] {taskinstance.py:1159} INFO - Dependencies all met for dep_context=requeueable deps ti=<TaskInstance: stt_task.STT scheduled__2024-01-16T00:00:00+00:00 [queued]>
[2024-01-17T07:11:47.338+0000] {taskinstance.py:1361} INFO - Starting attempt 1 of 2
[2024-01-17T07:11:47.359+0000] {taskinstance.py:1382} INFO - Executing <Task(PythonOperator): STT> on 2024-01-16 00:00:00+00:00
[2024-01-17T07:11:47.393+0000] {standard_task_runner.py:57} INFO - Started process 141 to run task
[2024-01-17T07:11:47.397+0000] {standard_task_runner.py:84} INFO - Running: ['***', 'tasks', 'run', 'stt_task', 'STT', 'scheduled__2024-01-16T00:00:00+00:00', '--job-id', '64', '--raw', '--subdir', 'DAGS_FOLDER/task.py', '--cfg-path', '/tmp/tmpggntkql5']
[2024-01-17T07:11:47.403+0000] {standard_task_runner.py:85} INFO - Job 64: Subtask STT
[2024-01-17T07:11:47.491+0000] {task_command.py:416} INFO - Running <TaskInstance: stt_task.STT scheduled__2024-01-16T00:00:00+00:00 [running]> on host 33ce4c84e7d8
[2024-01-17T07:11:47.614+0000] {taskinstance.py:1662} INFO - Exporting env vars: AIRFLOW_CTX_DAG_OWNER='***' AIRFLOW_CTX_DAG_ID='stt_task' AIRFLOW_CTX_TASK_ID='STT' AIRFLOW_CTX_EXECUTION_DATE='2024-01-16T00:00:00+00:00' AIRFLOW_CTX_TRY_NUMBER='1' AIRFLOW_CTX_DAG_RUN_ID='scheduled__2024-01-16T00:00:00+00:00'
[2024-01-17T07:11:47.619+0000] {taskinstance.py:1937} ERROR - Task failed with exception
Traceback (most recent call last):
  File "/home/airflow/.local/lib/python3.9/site-packages/airflow/operators/python.py", line 192, in execute
    return_value = self.execute_callable()
  File "/home/airflow/.local/lib/python3.9/site-packages/airflow/operators/python.py", line 209, in execute_callable
    return self.python_callable(*self.op_args, **self.op_kwargs)
  File "/opt/airflow/dags/task.py", line 52, in STT
    to_db(table = 'STT', df = df)
UnboundLocalError: local variable 'df' referenced before assignment
[2024-01-17T07:11:47.641+0000] {taskinstance.py:1400} INFO - Marking task as UP_FOR_RETRY. dag_id=stt_task, task_id=STT, execution_date=20240116T000000, start_date=20240117T071147, end_date=20240117T071147
[2024-01-17T07:11:47.668+0000] {standard_task_runner.py:104} ERROR - Failed to execute job 64 for task STT (local variable 'df' referenced before assignment; 141)
[2024-01-17T07:11:47.692+0000] {local_task_job_runner.py:228} INFO - Task exited with return code 1
[2024-01-17T07:11:47.722+0000] {taskinstance.py:2778} INFO - 0 downstream tasks scheduled from follow-on schedule check
