[2024-01-20T03:06:01.119+0000] {taskinstance.py:1159} INFO - Dependencies all met for dep_context=non-requeueable deps ti=<TaskInstance: stt_task.STT scheduled__2024-01-19T00:00:00+00:00 [queued]>
[2024-01-20T03:06:01.133+0000] {taskinstance.py:1159} INFO - Dependencies all met for dep_context=requeueable deps ti=<TaskInstance: stt_task.STT scheduled__2024-01-19T00:00:00+00:00 [queued]>
[2024-01-20T03:06:01.134+0000] {taskinstance.py:1361} INFO - Starting attempt 2 of 2
[2024-01-20T03:06:01.154+0000] {taskinstance.py:1382} INFO - Executing <Task(PythonOperator): STT> on 2024-01-19 00:00:00+00:00
[2024-01-20T03:06:01.169+0000] {standard_task_runner.py:57} INFO - Started process 1820 to run task
[2024-01-20T03:06:01.174+0000] {standard_task_runner.py:84} INFO - Running: ['***', 'tasks', 'run', 'stt_task', 'STT', 'scheduled__2024-01-19T00:00:00+00:00', '--job-id', '76', '--raw', '--subdir', 'DAGS_FOLDER/task.py', '--cfg-path', '/tmp/tmpa650v08l']
[2024-01-20T03:06:01.184+0000] {standard_task_runner.py:85} INFO - Job 76: Subtask STT
[2024-01-20T03:06:01.248+0000] {task_command.py:416} INFO - Running <TaskInstance: stt_task.STT scheduled__2024-01-19T00:00:00+00:00 [running]> on host a8fcb1faa919
[2024-01-20T03:06:01.337+0000] {taskinstance.py:1662} INFO - Exporting env vars: AIRFLOW_CTX_DAG_OWNER='***' AIRFLOW_CTX_DAG_ID='stt_task' AIRFLOW_CTX_TASK_ID='STT' AIRFLOW_CTX_EXECUTION_DATE='2024-01-19T00:00:00+00:00' AIRFLOW_CTX_TRY_NUMBER='2' AIRFLOW_CTX_DAG_RUN_ID='scheduled__2024-01-19T00:00:00+00:00'
[2024-01-20T03:06:01.339+0000] {taskinstance.py:1937} ERROR - Task failed with exception
Traceback (most recent call last):
  File "/home/airflow/.local/lib/python3.9/site-packages/airflow/operators/python.py", line 192, in execute
    return_value = self.execute_callable()
  File "/home/airflow/.local/lib/python3.9/site-packages/airflow/operators/python.py", line 209, in execute_callable
    return self.python_callable(*self.op_args, **self.op_kwargs)
  File "/opt/airflow/dags/task.py", line 52, in STT
    to_db(table = 'STT', df = df)
UnboundLocalError: local variable 'df' referenced before assignment
[2024-01-20T03:06:01.349+0000] {taskinstance.py:1400} INFO - Marking task as FAILED. dag_id=stt_task, task_id=STT, execution_date=20240119T000000, start_date=20240120T030601, end_date=20240120T030601
[2024-01-20T03:06:01.362+0000] {standard_task_runner.py:104} ERROR - Failed to execute job 76 for task STT (local variable 'df' referenced before assignment; 1820)
[2024-01-20T03:06:01.388+0000] {local_task_job_runner.py:228} INFO - Task exited with return code 1
[2024-01-20T03:06:01.406+0000] {taskinstance.py:2778} INFO - 0 downstream tasks scheduled from follow-on schedule check
