[2024-03-24T05:32:59.390+0000] {taskinstance.py:1159} INFO - Dependencies all met for dep_context=non-requeueable deps ti=<TaskInstance: stt_task.STT manual__2024-03-24T05:31:48.034088+00:00 [queued]>
[2024-03-24T05:32:59.406+0000] {taskinstance.py:1159} INFO - Dependencies all met for dep_context=requeueable deps ti=<TaskInstance: stt_task.STT manual__2024-03-24T05:31:48.034088+00:00 [queued]>
[2024-03-24T05:32:59.407+0000] {taskinstance.py:1361} INFO - Starting attempt 2 of 2
[2024-03-24T05:32:59.427+0000] {taskinstance.py:1382} INFO - Executing <Task(PythonOperator): STT> on 2024-03-24 05:31:48.034088+00:00
[2024-03-24T05:32:59.434+0000] {standard_task_runner.py:57} INFO - Started process 222 to run task
[2024-03-24T05:32:59.438+0000] {standard_task_runner.py:84} INFO - Running: ['***', 'tasks', 'run', 'stt_task', 'STT', 'manual__2024-03-24T05:31:48.034088+00:00', '--job-id', '37', '--raw', '--subdir', 'DAGS_FOLDER/task.py', '--cfg-path', '/tmp/tmpp_kaftlh']
[2024-03-24T05:32:59.445+0000] {standard_task_runner.py:85} INFO - Job 37: Subtask STT
[2024-03-24T05:32:59.523+0000] {task_command.py:416} INFO - Running <TaskInstance: stt_task.STT manual__2024-03-24T05:31:48.034088+00:00 [running]> on host 6fe5f6995c4e
[2024-03-24T05:32:59.673+0000] {taskinstance.py:1662} INFO - Exporting env vars: AIRFLOW_CTX_DAG_OWNER='***' AIRFLOW_CTX_DAG_ID='stt_task' AIRFLOW_CTX_TASK_ID='STT' AIRFLOW_CTX_EXECUTION_DATE='2024-03-24T05:31:48.034088+00:00' AIRFLOW_CTX_TRY_NUMBER='2' AIRFLOW_CTX_DAG_RUN_ID='manual__2024-03-24T05:31:48.034088+00:00'
[2024-03-24T05:32:59.679+0000] {logging_mixin.py:154} INFO - b'{"language": "ko-KR", "completion": "sync", "callback": null, "userdata": null, "wordAlignment": true, "fullText": true, "forbiddens": null, "boostings": null, "diarization": null}'
[2024-03-24T05:33:08.678+0000] {taskinstance.py:1937} ERROR - Task failed with exception
Traceback (most recent call last):
  File "/home/airflow/.local/lib/python3.9/site-packages/airflow/operators/python.py", line 192, in execute
    return_value = self.execute_callable()
  File "/home/airflow/.local/lib/python3.9/site-packages/airflow/operators/python.py", line 209, in execute_callable
    return self.python_callable(*self.op_args, **self.op_kwargs)
  File "/opt/airflow/dags/task.py", line 45, in STT
    user_id = get_user_id(user_name)
  File "/opt/airflow/dags/function/clova_function.py", line 158, in get_user_id
    return str(result['user_id'])
TypeError: 'NoneType' object is not subscriptable
[2024-03-24T05:33:08.700+0000] {taskinstance.py:1400} INFO - Marking task as FAILED. dag_id=stt_task, task_id=STT, execution_date=20240324T053148, start_date=20240324T053259, end_date=20240324T053308
[2024-03-24T05:33:08.962+0000] {standard_task_runner.py:104} ERROR - Failed to execute job 37 for task STT ('NoneType' object is not subscriptable; 222)
[2024-03-24T05:33:08.997+0000] {local_task_job_runner.py:228} INFO - Task exited with return code 1
[2024-03-24T05:33:09.026+0000] {taskinstance.py:2778} INFO - 0 downstream tasks scheduled from follow-on schedule check
