[2024-01-16T06:38:23.191+0000] {taskinstance.py:1159} INFO - Dependencies all met for dep_context=non-requeueable deps ti=<TaskInstance: STT-files.STT manual__2024-01-16T06:37:43.438623+00:00 [queued]>
[2024-01-16T06:38:23.315+0000] {taskinstance.py:1159} INFO - Dependencies all met for dep_context=requeueable deps ti=<TaskInstance: STT-files.STT manual__2024-01-16T06:37:43.438623+00:00 [queued]>
[2024-01-16T06:38:23.317+0000] {taskinstance.py:1361} INFO - Starting attempt 1 of 2
[2024-01-16T06:38:23.395+0000] {taskinstance.py:1382} INFO - Executing <Task(PythonOperator): STT> on 2024-01-16 06:37:43.438623+00:00
[2024-01-16T06:38:23.651+0000] {standard_task_runner.py:57} INFO - Started process 115 to run task
[2024-01-16T06:38:23.701+0000] {standard_task_runner.py:84} INFO - Running: ['***', 'tasks', 'run', 'STT-files', 'STT', 'manual__2024-01-16T06:37:43.438623+00:00', '--job-id', '39', '--raw', '--subdir', 'DAGS_FOLDER/task.py', '--cfg-path', '/tmp/tmp6cb04pb7']
[2024-01-16T06:38:23.769+0000] {standard_task_runner.py:85} INFO - Job 39: Subtask STT
[2024-01-16T06:38:24.281+0000] {task_command.py:416} INFO - Running <TaskInstance: STT-files.STT manual__2024-01-16T06:37:43.438623+00:00 [running]> on host 00276c0ab732
[2024-01-16T06:38:33.371+0000] {taskinstance.py:1662} INFO - Exporting env vars: AIRFLOW_CTX_DAG_OWNER='***' AIRFLOW_CTX_DAG_ID='STT-files' AIRFLOW_CTX_TASK_ID='STT' AIRFLOW_CTX_EXECUTION_DATE='2024-01-16T06:37:43.438623+00:00' AIRFLOW_CTX_TRY_NUMBER='1' AIRFLOW_CTX_DAG_RUN_ID='manual__2024-01-16T06:37:43.438623+00:00'
[2024-01-16T06:38:33.376+0000] {taskinstance.py:1937} ERROR - Task failed with exception
Traceback (most recent call last):
  File "/home/airflow/.local/lib/python3.9/site-packages/airflow/operators/python.py", line 192, in execute
    return_value = self.execute_callable()
  File "/home/airflow/.local/lib/python3.9/site-packages/airflow/operators/python.py", line 209, in execute_callable
    return self.python_callable(*self.op_args, **self.op_kwargs)
  File "/opt/airflow/dags/function/clova_function.py", line 176, in STT
    folder_path = '/Users/choi-junyong/github/connectslab/dags/m4a/' + date_num
NameError: name 'date_num' is not defined
[2024-01-16T06:38:33.440+0000] {taskinstance.py:1400} INFO - Marking task as UP_FOR_RETRY. dag_id=STT-files, task_id=STT, execution_date=20240116T063743, start_date=20240116T063823, end_date=20240116T063833
[2024-01-16T06:38:33.496+0000] {standard_task_runner.py:104} ERROR - Failed to execute job 39 for task STT (name 'date_num' is not defined; 115)
[2024-01-16T06:38:33.733+0000] {local_task_job_runner.py:228} INFO - Task exited with return code 1
[2024-01-16T06:38:33.821+0000] {taskinstance.py:2778} INFO - 0 downstream tasks scheduled from follow-on schedule check
