[2024-04-02T11:16:08.270+0000] {taskinstance.py:1159} INFO - Dependencies all met for dep_context=non-requeueable deps ti=<TaskInstance: stt_task.STT manual__2024-04-02T11:16:06.438202+00:00 [queued]>
[2024-04-02T11:16:08.282+0000] {taskinstance.py:1159} INFO - Dependencies all met for dep_context=requeueable deps ti=<TaskInstance: stt_task.STT manual__2024-04-02T11:16:06.438202+00:00 [queued]>
[2024-04-02T11:16:08.283+0000] {taskinstance.py:1361} INFO - Starting attempt 1 of 2
[2024-04-02T11:16:08.303+0000] {taskinstance.py:1382} INFO - Executing <Task(PythonOperator): STT> on 2024-04-02 11:16:06.438202+00:00
[2024-04-02T11:16:08.309+0000] {standard_task_runner.py:57} INFO - Started process 114 to run task
[2024-04-02T11:16:08.313+0000] {standard_task_runner.py:84} INFO - Running: ['***', 'tasks', 'run', 'stt_task', 'STT', 'manual__2024-04-02T11:16:06.438202+00:00', '--job-id', '63', '--raw', '--subdir', 'DAGS_FOLDER/task.py', '--cfg-path', '/tmp/tmp61fb6pn9']
[2024-04-02T11:16:08.317+0000] {standard_task_runner.py:85} INFO - Job 63: Subtask STT
[2024-04-02T11:16:08.371+0000] {task_command.py:416} INFO - Running <TaskInstance: stt_task.STT manual__2024-04-02T11:16:06.438202+00:00 [running]> on host bd3757cb365e
[2024-04-02T11:16:08.462+0000] {taskinstance.py:1662} INFO - Exporting env vars: AIRFLOW_CTX_DAG_OWNER='***' AIRFLOW_CTX_DAG_ID='stt_task' AIRFLOW_CTX_TASK_ID='STT' AIRFLOW_CTX_EXECUTION_DATE='2024-04-02T11:16:06.438202+00:00' AIRFLOW_CTX_TRY_NUMBER='1' AIRFLOW_CTX_DAG_RUN_ID='manual__2024-04-02T11:16:06.438202+00:00'
[2024-04-02T11:16:08.465+0000] {logging_mixin.py:154} INFO - b'{"language": "ko-KR", "completion": "sync", "callback": null, "userdata": null, "wordAlignment": true, "fullText": true, "forbiddens": null, "boostings": null, "diarization": null}'
[2024-04-02T11:16:16.354+0000] {taskinstance.py:1937} ERROR - Task failed with exception
Traceback (most recent call last):
  File "/home/airflow/.local/lib/python3.9/site-packages/airflow/operators/python.py", line 192, in execute
    return_value = self.execute_callable()
  File "/home/airflow/.local/lib/python3.9/site-packages/airflow/operators/python.py", line 209, in execute_callable
    return self.python_callable(*self.op_args, **self.op_kwargs)
  File "/opt/airflow/dags/task.py", line 31, in STT
    user_name, user_id = get_user_name(audio_file), get_user_id(user_name)
UnboundLocalError: local variable 'user_name' referenced before assignment
[2024-04-02T11:16:16.572+0000] {taskinstance.py:1400} INFO - Marking task as UP_FOR_RETRY. dag_id=stt_task, task_id=STT, execution_date=20240402T111606, start_date=20240402T111608, end_date=20240402T111616
[2024-04-02T11:16:16.588+0000] {standard_task_runner.py:104} ERROR - Failed to execute job 63 for task STT (local variable 'user_name' referenced before assignment; 114)
[2024-04-02T11:16:16.616+0000] {local_task_job_runner.py:228} INFO - Task exited with return code 1
[2024-04-02T11:16:16.632+0000] {taskinstance.py:2778} INFO - 0 downstream tasks scheduled from follow-on schedule check
