[2024-04-01T07:30:38.853+0000] {taskinstance.py:1159} INFO - Dependencies all met for dep_context=non-requeueable deps ti=<TaskInstance: stt_task.STT manual__2024-04-01T07:30:36.085336+00:00 [queued]>
[2024-04-01T07:30:38.867+0000] {taskinstance.py:1159} INFO - Dependencies all met for dep_context=requeueable deps ti=<TaskInstance: stt_task.STT manual__2024-04-01T07:30:36.085336+00:00 [queued]>
[2024-04-01T07:30:38.868+0000] {taskinstance.py:1361} INFO - Starting attempt 1 of 2
[2024-04-01T07:30:38.885+0000] {taskinstance.py:1382} INFO - Executing <Task(PythonOperator): STT> on 2024-04-01 07:30:36.085336+00:00
[2024-04-01T07:30:38.892+0000] {standard_task_runner.py:57} INFO - Started process 1922 to run task
[2024-04-01T07:30:38.898+0000] {standard_task_runner.py:84} INFO - Running: ['***', 'tasks', 'run', 'stt_task', 'STT', 'manual__2024-04-01T07:30:36.085336+00:00', '--job-id', '51', '--raw', '--subdir', 'DAGS_FOLDER/task.py', '--cfg-path', '/tmp/tmpjxwtztcz']
[2024-04-01T07:30:38.902+0000] {standard_task_runner.py:85} INFO - Job 51: Subtask STT
[2024-04-01T07:30:38.969+0000] {task_command.py:416} INFO - Running <TaskInstance: stt_task.STT manual__2024-04-01T07:30:36.085336+00:00 [running]> on host 139ee04fed22
[2024-04-01T07:30:39.073+0000] {taskinstance.py:1662} INFO - Exporting env vars: AIRFLOW_CTX_DAG_OWNER='***' AIRFLOW_CTX_DAG_ID='stt_task' AIRFLOW_CTX_TASK_ID='STT' AIRFLOW_CTX_EXECUTION_DATE='2024-04-01T07:30:36.085336+00:00' AIRFLOW_CTX_TRY_NUMBER='1' AIRFLOW_CTX_DAG_RUN_ID='manual__2024-04-01T07:30:36.085336+00:00'
[2024-04-01T07:30:39.084+0000] {logging_mixin.py:154} INFO - b'{"language": "ko-KR", "completion": "sync", "callback": null, "userdata": null, "wordAlignment": true, "fullText": true, "forbiddens": null, "boostings": null, "diarization": null}'
[2024-04-01T07:30:46.344+0000] {taskinstance.py:1937} ERROR - Task failed with exception
Traceback (most recent call last):
  File "/home/airflow/.local/lib/python3.9/site-packages/airflow/operators/python.py", line 192, in execute
    return_value = self.execute_callable()
  File "/home/airflow/.local/lib/python3.9/site-packages/airflow/operators/python.py", line 209, in execute_callable
    return self.python_callable(*self.op_args, **self.op_kwargs)
  File "/opt/airflow/dags/task.py", line 112, in STT
    user_name, user_id = get_user_name(audio_file), get_user_id(user_name)
UnboundLocalError: local variable 'user_name' referenced before assignment
[2024-04-01T07:30:47.608+0000] {taskinstance.py:1400} INFO - Marking task as UP_FOR_RETRY. dag_id=stt_task, task_id=STT, execution_date=20240401T073036, start_date=20240401T073038, end_date=20240401T073047
[2024-04-01T07:30:47.624+0000] {standard_task_runner.py:104} ERROR - Failed to execute job 51 for task STT (local variable 'user_name' referenced before assignment; 1922)
[2024-04-01T07:30:47.644+0000] {local_task_job_runner.py:228} INFO - Task exited with return code 1
[2024-04-01T07:30:47.665+0000] {taskinstance.py:2778} INFO - 0 downstream tasks scheduled from follow-on schedule check
