[2024-04-01T07:31:49.207+0000] {taskinstance.py:1159} INFO - Dependencies all met for dep_context=non-requeueable deps ti=<TaskInstance: stt_task.STT manual__2024-04-01T07:30:36.085336+00:00 [queued]>
[2024-04-01T07:31:49.219+0000] {taskinstance.py:1159} INFO - Dependencies all met for dep_context=requeueable deps ti=<TaskInstance: stt_task.STT manual__2024-04-01T07:30:36.085336+00:00 [queued]>
[2024-04-01T07:31:49.220+0000] {taskinstance.py:1361} INFO - Starting attempt 2 of 2
[2024-04-01T07:31:49.235+0000] {taskinstance.py:1382} INFO - Executing <Task(PythonOperator): STT> on 2024-04-01 07:30:36.085336+00:00
[2024-04-01T07:31:49.242+0000] {standard_task_runner.py:57} INFO - Started process 1939 to run task
[2024-04-01T07:31:49.245+0000] {standard_task_runner.py:84} INFO - Running: ['***', 'tasks', 'run', 'stt_task', 'STT', 'manual__2024-04-01T07:30:36.085336+00:00', '--job-id', '52', '--raw', '--subdir', 'DAGS_FOLDER/task.py', '--cfg-path', '/tmp/tmpyy_xbzgh']
[2024-04-01T07:31:49.249+0000] {standard_task_runner.py:85} INFO - Job 52: Subtask STT
[2024-04-01T07:31:49.305+0000] {task_command.py:416} INFO - Running <TaskInstance: stt_task.STT manual__2024-04-01T07:30:36.085336+00:00 [running]> on host 139ee04fed22
[2024-04-01T07:31:49.399+0000] {taskinstance.py:1662} INFO - Exporting env vars: AIRFLOW_CTX_DAG_OWNER='***' AIRFLOW_CTX_DAG_ID='stt_task' AIRFLOW_CTX_TASK_ID='STT' AIRFLOW_CTX_EXECUTION_DATE='2024-04-01T07:30:36.085336+00:00' AIRFLOW_CTX_TRY_NUMBER='2' AIRFLOW_CTX_DAG_RUN_ID='manual__2024-04-01T07:30:36.085336+00:00'
[2024-04-01T07:31:49.403+0000] {logging_mixin.py:154} INFO - b'{"language": "ko-KR", "completion": "sync", "callback": null, "userdata": null, "wordAlignment": true, "fullText": true, "forbiddens": null, "boostings": null, "diarization": null}'
[2024-04-01T07:31:55.988+0000] {taskinstance.py:1937} ERROR - Task failed with exception
Traceback (most recent call last):
  File "/home/airflow/.local/lib/python3.9/site-packages/airflow/operators/python.py", line 192, in execute
    return_value = self.execute_callable()
  File "/home/airflow/.local/lib/python3.9/site-packages/airflow/operators/python.py", line 209, in execute_callable
    return self.python_callable(*self.op_args, **self.op_kwargs)
  File "/opt/airflow/dags/task.py", line 112, in STT
    user_name, user_id = get_user_name(audio_file), get_user_id(user_name)
UnboundLocalError: local variable 'user_name' referenced before assignment
[2024-04-01T07:31:56.181+0000] {taskinstance.py:1400} INFO - Marking task as FAILED. dag_id=stt_task, task_id=STT, execution_date=20240401T073036, start_date=20240401T073149, end_date=20240401T073156
[2024-04-01T07:31:56.196+0000] {standard_task_runner.py:104} ERROR - Failed to execute job 52 for task STT (local variable 'user_name' referenced before assignment; 1939)
[2024-04-01T07:31:56.222+0000] {local_task_job_runner.py:228} INFO - Task exited with return code 1
[2024-04-01T07:31:56.239+0000] {taskinstance.py:2778} INFO - 0 downstream tasks scheduled from follow-on schedule check
