[2024-01-16T06:54:51.574+0000] {taskinstance.py:1159} INFO - Dependencies all met for dep_context=non-requeueable deps ti=<TaskInstance: STT-files.STT manual__2024-01-16T06:54:49.805807+00:00 [queued]>
[2024-01-16T06:54:51.589+0000] {taskinstance.py:1159} INFO - Dependencies all met for dep_context=requeueable deps ti=<TaskInstance: STT-files.STT manual__2024-01-16T06:54:49.805807+00:00 [queued]>
[2024-01-16T06:54:51.590+0000] {taskinstance.py:1361} INFO - Starting attempt 1 of 2
[2024-01-16T06:54:51.612+0000] {taskinstance.py:1382} INFO - Executing <Task(PythonOperator): STT> on 2024-01-16 06:54:49.805807+00:00
[2024-01-16T06:54:51.621+0000] {standard_task_runner.py:57} INFO - Started process 332 to run task
[2024-01-16T06:54:51.626+0000] {standard_task_runner.py:84} INFO - Running: ['***', 'tasks', 'run', 'STT-files', 'STT', 'manual__2024-01-16T06:54:49.805807+00:00', '--job-id', '48', '--raw', '--subdir', 'DAGS_FOLDER/task.py', '--cfg-path', '/tmp/tmpo8inxc7i']
[2024-01-16T06:54:51.630+0000] {standard_task_runner.py:85} INFO - Job 48: Subtask STT
[2024-01-16T06:54:51.692+0000] {task_command.py:416} INFO - Running <TaskInstance: STT-files.STT manual__2024-01-16T06:54:49.805807+00:00 [running]> on host 00276c0ab732
[2024-01-16T06:54:51.779+0000] {taskinstance.py:1662} INFO - Exporting env vars: AIRFLOW_CTX_DAG_OWNER='***' AIRFLOW_CTX_DAG_ID='STT-files' AIRFLOW_CTX_TASK_ID='STT' AIRFLOW_CTX_EXECUTION_DATE='2024-01-16T06:54:49.805807+00:00' AIRFLOW_CTX_TRY_NUMBER='1' AIRFLOW_CTX_DAG_RUN_ID='manual__2024-01-16T06:54:49.805807+00:00'
[2024-01-16T06:54:51.783+0000] {logging_mixin.py:154} INFO - b'{"language": "ko-KR", "completion": "sync", "callback": null, "userdata": null, "wordAlignment": true, "fullText": true, "forbiddens": null, "boostings": null, "diarization": null}'
[2024-01-16T06:55:03.068+0000] {taskinstance.py:1937} ERROR - Task failed with exception
Traceback (most recent call last):
  File "/home/airflow/.local/lib/python3.9/site-packages/airflow/operators/python.py", line 192, in execute
    return_value = self.execute_callable()
  File "/home/airflow/.local/lib/python3.9/site-packages/airflow/operators/python.py", line 209, in execute_callable
    return self.python_callable(*self.op_args, **self.op_kwargs)
  File "/opt/airflow/dags/function/clova_function.py", line 208, in STT
    to_db(table = STT, df = df)
  File "/opt/airflow/dags/function/database.py", line 14, in to_db
    df.to_sql(table, con=engine, if_exists='replace', index=False)
  File "/home/airflow/.local/lib/python3.9/site-packages/pandas/util/_decorators.py", line 333, in wrapper
    return func(*args, **kwargs)
  File "/home/airflow/.local/lib/python3.9/site-packages/pandas/core/generic.py", line 3008, in to_sql
    return sql.to_sql(
  File "/home/airflow/.local/lib/python3.9/site-packages/pandas/io/sql.py", line 788, in to_sql
    return pandas_sql.to_sql(
  File "/home/airflow/.local/lib/python3.9/site-packages/pandas/io/sql.py", line 1948, in to_sql
    table = self.prep_table(
  File "/home/airflow/.local/lib/python3.9/site-packages/pandas/io/sql.py", line 1842, in prep_table
    table = SQLTable(
  File "/home/airflow/.local/lib/python3.9/site-packages/pandas/io/sql.py", line 907, in __init__
    if not len(self.name):
TypeError: object of type 'function' has no len()
[2024-01-16T06:55:03.093+0000] {taskinstance.py:1400} INFO - Marking task as UP_FOR_RETRY. dag_id=STT-files, task_id=STT, execution_date=20240116T065449, start_date=20240116T065451, end_date=20240116T065503
[2024-01-16T06:55:03.118+0000] {standard_task_runner.py:104} ERROR - Failed to execute job 48 for task STT (object of type 'function' has no len(); 332)
[2024-01-16T06:55:03.159+0000] {local_task_job_runner.py:228} INFO - Task exited with return code 1
[2024-01-16T06:55:03.177+0000] {taskinstance.py:2778} INFO - 0 downstream tasks scheduled from follow-on schedule check
