[2024-01-17T07:11:47.205+0000] {taskinstance.py:1159} INFO - Dependencies all met for dep_context=non-requeueable deps ti=<TaskInstance: stt_task.STT manual__2024-01-17T07:11:45.135056+00:00 [queued]>
[2024-01-17T07:11:47.221+0000] {taskinstance.py:1159} INFO - Dependencies all met for dep_context=requeueable deps ti=<TaskInstance: stt_task.STT manual__2024-01-17T07:11:45.135056+00:00 [queued]>
[2024-01-17T07:11:47.222+0000] {taskinstance.py:1361} INFO - Starting attempt 1 of 2
[2024-01-17T07:11:47.248+0000] {taskinstance.py:1382} INFO - Executing <Task(PythonOperator): STT> on 2024-01-17 07:11:45.135056+00:00
[2024-01-17T07:11:47.288+0000] {standard_task_runner.py:57} INFO - Started process 140 to run task
[2024-01-17T07:11:47.292+0000] {standard_task_runner.py:84} INFO - Running: ['***', 'tasks', 'run', 'stt_task', 'STT', 'manual__2024-01-17T07:11:45.135056+00:00', '--job-id', '63', '--raw', '--subdir', 'DAGS_FOLDER/task.py', '--cfg-path', '/tmp/tmpapzsl68e']
[2024-01-17T07:11:47.298+0000] {standard_task_runner.py:85} INFO - Job 63: Subtask STT
[2024-01-17T07:11:47.372+0000] {task_command.py:416} INFO - Running <TaskInstance: stt_task.STT manual__2024-01-17T07:11:45.135056+00:00 [running]> on host 33ce4c84e7d8
[2024-01-17T07:11:47.500+0000] {taskinstance.py:1662} INFO - Exporting env vars: AIRFLOW_CTX_DAG_OWNER='***' AIRFLOW_CTX_DAG_ID='stt_task' AIRFLOW_CTX_TASK_ID='STT' AIRFLOW_CTX_EXECUTION_DATE='2024-01-17T07:11:45.135056+00:00' AIRFLOW_CTX_TRY_NUMBER='1' AIRFLOW_CTX_DAG_RUN_ID='manual__2024-01-17T07:11:45.135056+00:00'
[2024-01-17T07:11:47.506+0000] {taskinstance.py:1937} ERROR - Task failed with exception
Traceback (most recent call last):
  File "/home/airflow/.local/lib/python3.9/site-packages/airflow/operators/python.py", line 192, in execute
    return_value = self.execute_callable()
  File "/home/airflow/.local/lib/python3.9/site-packages/airflow/operators/python.py", line 209, in execute_callable
    return self.python_callable(*self.op_args, **self.op_kwargs)
  File "/opt/airflow/dags/task.py", line 52, in STT
    to_db(table = 'STT', df = df)
UnboundLocalError: local variable 'df' referenced before assignment
[2024-01-17T07:11:47.519+0000] {taskinstance.py:1400} INFO - Marking task as UP_FOR_RETRY. dag_id=stt_task, task_id=STT, execution_date=20240117T071145, start_date=20240117T071147, end_date=20240117T071147
[2024-01-17T07:11:47.536+0000] {standard_task_runner.py:104} ERROR - Failed to execute job 63 for task STT (local variable 'df' referenced before assignment; 140)
[2024-01-17T07:11:47.548+0000] {local_task_job_runner.py:228} INFO - Task exited with return code 1
[2024-01-17T07:11:47.586+0000] {taskinstance.py:2778} INFO - 0 downstream tasks scheduled from follow-on schedule check
