[2024-01-17T07:12:49.578+0000] {taskinstance.py:1159} INFO - Dependencies all met for dep_context=non-requeueable deps ti=<TaskInstance: stt_task.STT manual__2024-01-17T07:11:45.135056+00:00 [queued]>
[2024-01-17T07:12:49.616+0000] {taskinstance.py:1159} INFO - Dependencies all met for dep_context=requeueable deps ti=<TaskInstance: stt_task.STT manual__2024-01-17T07:11:45.135056+00:00 [queued]>
[2024-01-17T07:12:49.618+0000] {taskinstance.py:1361} INFO - Starting attempt 2 of 2
[2024-01-17T07:12:49.648+0000] {taskinstance.py:1382} INFO - Executing <Task(PythonOperator): STT> on 2024-01-17 07:11:45.135056+00:00
[2024-01-17T07:12:49.670+0000] {standard_task_runner.py:57} INFO - Started process 160 to run task
[2024-01-17T07:12:49.681+0000] {standard_task_runner.py:84} INFO - Running: ['***', 'tasks', 'run', 'stt_task', 'STT', 'manual__2024-01-17T07:11:45.135056+00:00', '--job-id', '66', '--raw', '--subdir', 'DAGS_FOLDER/task.py', '--cfg-path', '/tmp/tmp2ve3b5ap']
[2024-01-17T07:12:49.685+0000] {standard_task_runner.py:85} INFO - Job 66: Subtask STT
[2024-01-17T07:12:49.801+0000] {task_command.py:416} INFO - Running <TaskInstance: stt_task.STT manual__2024-01-17T07:11:45.135056+00:00 [running]> on host 33ce4c84e7d8
[2024-01-17T07:12:49.963+0000] {taskinstance.py:1662} INFO - Exporting env vars: AIRFLOW_CTX_DAG_OWNER='***' AIRFLOW_CTX_DAG_ID='stt_task' AIRFLOW_CTX_TASK_ID='STT' AIRFLOW_CTX_EXECUTION_DATE='2024-01-17T07:11:45.135056+00:00' AIRFLOW_CTX_TRY_NUMBER='2' AIRFLOW_CTX_DAG_RUN_ID='manual__2024-01-17T07:11:45.135056+00:00'
[2024-01-17T07:12:49.967+0000] {taskinstance.py:1937} ERROR - Task failed with exception
Traceback (most recent call last):
  File "/home/airflow/.local/lib/python3.9/site-packages/airflow/operators/python.py", line 192, in execute
    return_value = self.execute_callable()
  File "/home/airflow/.local/lib/python3.9/site-packages/airflow/operators/python.py", line 209, in execute_callable
    return self.python_callable(*self.op_args, **self.op_kwargs)
  File "/opt/airflow/dags/task.py", line 52, in STT
    to_db(table = 'STT', df = df)
UnboundLocalError: local variable 'df' referenced before assignment
[2024-01-17T07:12:49.994+0000] {taskinstance.py:1400} INFO - Marking task as FAILED. dag_id=stt_task, task_id=STT, execution_date=20240117T071145, start_date=20240117T071249, end_date=20240117T071249
[2024-01-17T07:12:50.029+0000] {standard_task_runner.py:104} ERROR - Failed to execute job 66 for task STT (local variable 'df' referenced before assignment; 160)
[2024-01-17T07:12:50.064+0000] {local_task_job_runner.py:228} INFO - Task exited with return code 1
[2024-01-17T07:12:50.135+0000] {taskinstance.py:2778} INFO - 0 downstream tasks scheduled from follow-on schedule check
