[2024-01-16T07:03:23.186+0000] {taskinstance.py:1159} INFO - Dependencies all met for dep_context=non-requeueable deps ti=<TaskInstance: stt_task.STT manual__2024-01-16T07:03:21.573991+00:00 [queued]>
[2024-01-16T07:03:23.200+0000] {taskinstance.py:1159} INFO - Dependencies all met for dep_context=requeueable deps ti=<TaskInstance: stt_task.STT manual__2024-01-16T07:03:21.573991+00:00 [queued]>
[2024-01-16T07:03:23.201+0000] {taskinstance.py:1361} INFO - Starting attempt 1 of 2
[2024-01-16T07:03:23.220+0000] {taskinstance.py:1382} INFO - Executing <Task(PythonOperator): STT> on 2024-01-16 07:03:21.573991+00:00
[2024-01-16T07:03:23.226+0000] {standard_task_runner.py:57} INFO - Started process 460 to run task
[2024-01-16T07:03:23.230+0000] {standard_task_runner.py:84} INFO - Running: ['***', 'tasks', 'run', 'stt_task', 'STT', 'manual__2024-01-16T07:03:21.573991+00:00', '--job-id', '55', '--raw', '--subdir', 'DAGS_FOLDER/task.py', '--cfg-path', '/tmp/tmpz5lli9_o']
[2024-01-16T07:03:23.234+0000] {standard_task_runner.py:85} INFO - Job 55: Subtask STT
[2024-01-16T07:03:23.293+0000] {task_command.py:416} INFO - Running <TaskInstance: stt_task.STT manual__2024-01-16T07:03:21.573991+00:00 [running]> on host 00276c0ab732
[2024-01-16T07:03:23.381+0000] {taskinstance.py:1662} INFO - Exporting env vars: AIRFLOW_CTX_DAG_OWNER='***' AIRFLOW_CTX_DAG_ID='stt_task' AIRFLOW_CTX_TASK_ID='STT' AIRFLOW_CTX_EXECUTION_DATE='2024-01-16T07:03:21.573991+00:00' AIRFLOW_CTX_TRY_NUMBER='1' AIRFLOW_CTX_DAG_RUN_ID='manual__2024-01-16T07:03:21.573991+00:00'
[2024-01-16T07:03:23.386+0000] {logging_mixin.py:154} INFO - b'{"language": "ko-KR", "completion": "sync", "callback": null, "userdata": null, "wordAlignment": true, "fullText": true, "forbiddens": null, "boostings": null, "diarization": null}'
[2024-01-16T07:03:31.294+0000] {taskinstance.py:1937} ERROR - Task failed with exception
Traceback (most recent call last):
  File "/home/airflow/.local/lib/python3.9/site-packages/airflow/operators/python.py", line 192, in execute
    return_value = self.execute_callable()
  File "/home/airflow/.local/lib/python3.9/site-packages/airflow/operators/python.py", line 209, in execute_callable
    return self.python_callable(*self.op_args, **self.op_kwargs)
  File "/opt/airflow/dags/task.py", line 45, in STT
    df = pd.DataFrame(data_list, columns=['user_id', 'user_name', '시작 시간', '종료 시간', '텍스트', '신뢰도', '화자', '텍스트 편집 여부', '날짜'])
NameError: name 'pd' is not defined
[2024-01-16T07:03:31.573+0000] {taskinstance.py:1400} INFO - Marking task as UP_FOR_RETRY. dag_id=stt_task, task_id=STT, execution_date=20240116T070321, start_date=20240116T070323, end_date=20240116T070331
[2024-01-16T07:03:31.590+0000] {standard_task_runner.py:104} ERROR - Failed to execute job 55 for task STT (name 'pd' is not defined; 460)
[2024-01-16T07:03:31.618+0000] {local_task_job_runner.py:228} INFO - Task exited with return code 1
[2024-01-16T07:03:31.635+0000] {taskinstance.py:2778} INFO - 0 downstream tasks scheduled from follow-on schedule check
