[2024-03-26T01:19:28.297+0000] {taskinstance.py:1159} INFO - Dependencies all met for dep_context=non-requeueable deps ti=<TaskInstance: stt_task.STT scheduled__2024-03-25T00:00:00+00:00 [queued]>
[2024-03-26T01:19:28.321+0000] {taskinstance.py:1159} INFO - Dependencies all met for dep_context=requeueable deps ti=<TaskInstance: stt_task.STT scheduled__2024-03-25T00:00:00+00:00 [queued]>
[2024-03-26T01:19:28.322+0000] {taskinstance.py:1361} INFO - Starting attempt 2 of 2
[2024-03-26T01:19:28.344+0000] {taskinstance.py:1382} INFO - Executing <Task(PythonOperator): STT> on 2024-03-25 00:00:00+00:00
[2024-03-26T01:19:28.352+0000] {standard_task_runner.py:57} INFO - Started process 2930 to run task
[2024-03-26T01:19:28.357+0000] {standard_task_runner.py:84} INFO - Running: ['***', 'tasks', 'run', 'stt_task', 'STT', 'scheduled__2024-03-25T00:00:00+00:00', '--job-id', '43', '--raw', '--subdir', 'DAGS_FOLDER/task.py', '--cfg-path', '/tmp/tmpz248j7h4']
[2024-03-26T01:19:28.362+0000] {standard_task_runner.py:85} INFO - Job 43: Subtask STT
[2024-03-26T01:19:28.428+0000] {task_command.py:416} INFO - Running <TaskInstance: stt_task.STT scheduled__2024-03-25T00:00:00+00:00 [running]> on host 6fe5f6995c4e
[2024-03-26T01:19:28.535+0000] {taskinstance.py:1662} INFO - Exporting env vars: AIRFLOW_CTX_DAG_OWNER='***' AIRFLOW_CTX_DAG_ID='stt_task' AIRFLOW_CTX_TASK_ID='STT' AIRFLOW_CTX_EXECUTION_DATE='2024-03-25T00:00:00+00:00' AIRFLOW_CTX_TRY_NUMBER='2' AIRFLOW_CTX_DAG_RUN_ID='scheduled__2024-03-25T00:00:00+00:00'
[2024-03-26T01:19:28.539+0000] {taskinstance.py:1937} ERROR - Task failed with exception
Traceback (most recent call last):
  File "/home/airflow/.local/lib/python3.9/site-packages/airflow/operators/python.py", line 192, in execute
    return_value = self.execute_callable()
  File "/home/airflow/.local/lib/python3.9/site-packages/airflow/operators/python.py", line 209, in execute_callable
    return self.python_callable(*self.op_args, **self.op_kwargs)
  File "/opt/airflow/dags/task.py", line 52, in STT
    to_db(df)
UnboundLocalError: local variable 'df' referenced before assignment
[2024-03-26T01:19:28.553+0000] {taskinstance.py:1400} INFO - Marking task as FAILED. dag_id=stt_task, task_id=STT, execution_date=20240325T000000, start_date=20240326T011928, end_date=20240326T011928
[2024-03-26T01:19:28.571+0000] {standard_task_runner.py:104} ERROR - Failed to execute job 43 for task STT (local variable 'df' referenced before assignment; 2930)
[2024-03-26T01:19:28.614+0000] {local_task_job_runner.py:228} INFO - Task exited with return code 1
[2024-03-26T01:19:28.645+0000] {taskinstance.py:2778} INFO - 0 downstream tasks scheduled from follow-on schedule check
